<mujoco model="planar walker">
  <include file="./common_xml/visual.xml"/>
  <include file="./common_xml/skybox.xml"/>
  <include file="./common_xml/materials.xml"/>

  <option timestep="0.0025"/>

  <statistic extent="2" center="0 0 1"/>

  <default>
    <joint damping=".1" armature="0.01" limited="true" solimplimit="0 .99 .01"/>
    <geom contype="1" conaffinity="0" friction=".7 .1 .1"/>
    <motor ctrlrange="-1 1" ctrllimited="true"/>
    <site size="0.01"/>
    <default class="walker">
      <geom material="self" type="capsule"/>
      <joint axis="0 -1 0"/>
    </default>
  </default>

  <worldbody>
    <geom name="floor" type="plane" conaffinity="1" pos="248 0 0" size="500 .8 .2" material="grid" zaxis="0 0 1"/>

    <geom name="box_00" type="box" conaffinity="1" pos="0 0 -10" size=".2 .8 .2" material="grid" rgba="1 0 0 1"/>
    <geom name="box_01" type="box" conaffinity="1" pos="0 0 -10" size=".2 .8 .2" material="grid" rgba="1 0 0 1"/>
    <geom name="box_02" type="box" conaffinity="1" pos="0 0 -10" size=".2 .8 .2" material="grid" rgba="1 0 0 1"/>
    <geom name="box_03" type="box" conaffinity="1" pos="0 0 -10" size=".2 .8 .2" material="grid" rgba="1 0 0 1"/>
    <geom name="box_04" type="box" conaffinity="1" pos="0 0 -10" size=".2 .8 .2" material="grid" rgba="1 0 0 1"/>
    <geom name="box_05" type="box" conaffinity="1" pos="0 0 -10" size=".2 .8 .2" material="grid" rgba="1 0 0 1"/>
    <geom name="box_06" type="box" conaffinity="1" pos="0 0 -10" size=".2 .8 .2" material="grid" rgba="1 0 0 1"/>
    <geom name="box_07" type="box" conaffinity="1" pos="0 0 -10" size=".2 .8 .2" material="grid" rgba="1 0 0 1"/>
    <geom name="box_08" type="box" conaffinity="1" pos="0 0 -10" size=".2 .8 .2" material="grid" rgba="1 0 0 1"/>
    <geom name="box_09" type="box" conaffinity="1" pos="0 0 -10" size=".2 .8 .2" material="grid" rgba="1 0 0 1"/>
    <geom name="box_10" type="box" conaffinity="1" pos="0 0 -10" size=".2 .8 .2" material="grid" rgba="1 0 0 1"/>
    <geom name="box_11" type="box" conaffinity="1" pos="0 0 -10" size=".2 .8 .2" material="grid" rgba="1 0 0 1"/>
    <geom name="box_12" type="box" conaffinity="1" pos="0 0 -10" size=".2 .8 .2" material="grid" rgba="1 0 0 1"/>
    <geom name="box_13" type="box" conaffinity="1" pos="0 0 -10" size=".2 .8 .2" material="grid" rgba="1 0 0 1"/>
    <geom name="box_14" type="box" conaffinity="1" pos="0 0 -10" size=".2 .8 .2" material="grid" rgba="1 0 0 1"/>
    <geom name="box_15" type="box" conaffinity="1" pos="0 0 -10" size=".2 .8 .2" material="grid" rgba="1 0 0 1"/>
    <geom name="box_16" type="box" conaffinity="1" pos="0 0 -10" size=".2 .8 .2" material="grid" rgba="1 0 0 1"/>
    <geom name="box_17" type="box" conaffinity="1" pos="0 0 -10" size=".2 .8 .2" material="grid" rgba="1 0 0 1"/>
    <geom name="box_18" type="box" conaffinity="1" pos="0 0 -10" size=".2 .8 .2" material="grid" rgba="1 0 0 1"/>
    <geom name="box_19" type="box" conaffinity="1" pos="0 0 -10" size=".2 .8 .2" material="grid" rgba="1 0 0 1"/>
    <geom name="box_20" type="box" conaffinity="1" pos="0 0 -10" size=".2 .8 .2" material="grid" rgba="1 0 0 1"/>
    <geom name="box_21" type="box" conaffinity="1" pos="0 0 -10" size=".2 .8 .2" material="grid" rgba="1 0 0 1"/>
    <geom name="box_22" type="box" conaffinity="1" pos="0 0 -10" size=".2 .8 .2" material="grid" rgba="1 0 0 1"/>
    <geom name="box_23" type="box" conaffinity="1" pos="0 0 -10" size=".2 .8 .2" material="grid" rgba="1 0 0 1"/>
    <geom name="box_24" type="box" conaffinity="1" pos="0 0 -10" size=".2 .8 .2" material="grid" rgba="1 0 0 1"/>

    <geom name="box_25" type="box" conaffinity="1" pos="0 0 -10" size=".2 .8 .2" material="grid" rgba="1 0 0 1"/>
    <geom name="box_26" type="box" conaffinity="1" pos="0 0 -10" size=".2 .8 .2" material="grid" rgba="1 0 0 1"/>
    <geom name="box_27" type="box" conaffinity="1" pos="0 0 -10" size=".2 .8 .2" material="grid" rgba="1 0 0 1"/>
    <geom name="box_28" type="box" conaffinity="1" pos="0 0 -10" size=".2 .8 .2" material="grid" rgba="1 0 0 1"/>
    <geom name="box_29" type="box" conaffinity="1" pos="0 0 -10" size=".2 .8 .2" material="grid" rgba="1 0 0 1"/>
    <geom name="box_30" type="box" conaffinity="1" pos="0 0 -10" size=".2 .8 .2" material="grid" rgba="1 0 0 1"/>
    <geom name="box_31" type="box" conaffinity="1" pos="0 0 -10" size=".2 .8 .2" material="grid" rgba="1 0 0 1"/>
    <geom name="box_32" type="box" conaffinity="1" pos="0 0 -10" size=".2 .8 .2" material="grid" rgba="1 0 0 1"/>
    <geom name="box_33" type="box" conaffinity="1" pos="0 0 -10" size=".2 .8 .2" material="grid" rgba="1 0 0 1"/>
    <geom name="box_34" type="box" conaffinity="1" pos="0 0 -10" size=".2 .8 .2" material="grid" rgba="1 0 0 1"/>
    <geom name="box_35" type="box" conaffinity="1" pos="0 0 -10" size=".2 .8 .2" material="grid" rgba="1 0 0 1"/>
    <geom name="box_36" type="box" conaffinity="1" pos="0 0 -10" size=".2 .8 .2" material="grid" rgba="1 0 0 1"/>
    <geom name="box_37" type="box" conaffinity="1" pos="0 0 -10" size=".2 .8 .2" material="grid" rgba="1 0 0 1"/>
    <geom name="box_38" type="box" conaffinity="1" pos="0 0 -10" size=".2 .8 .2" material="grid" rgba="1 0 0 1"/>
    <geom name="box_39" type="box" conaffinity="1" pos="0 0 -10" size=".2 .8 .2" material="grid" rgba="1 0 0 1"/>
    <geom name="box_40" type="box" conaffinity="1" pos="0 0 -10" size=".2 .8 .2" material="grid" rgba="1 0 0 1"/>
    <geom name="box_41" type="box" conaffinity="1" pos="0 0 -10" size=".2 .8 .2" material="grid" rgba="1 0 0 1"/>
    <geom name="box_42" type="box" conaffinity="1" pos="0 0 -10" size=".2 .8 .2" material="grid" rgba="1 0 0 1"/>
    <geom name="box_43" type="box" conaffinity="1" pos="0 0 -10" size=".2 .8 .2" material="grid" rgba="1 0 0 1"/>
    <geom name="box_44" type="box" conaffinity="1" pos="0 0 -10" size=".2 .8 .2" material="grid" rgba="1 0 0 1"/>
    <geom name="box_45" type="box" conaffinity="1" pos="0 0 -10" size=".2 .8 .2" material="grid" rgba="1 0 0 1"/>
    <geom name="box_46" type="box" conaffinity="1" pos="0 0 -10" size=".2 .8 .2" material="grid" rgba="1 0 0 1"/>
    <geom name="box_47" type="box" conaffinity="1" pos="0 0 -10" size=".2 .8 .2" material="grid" rgba="1 0 0 1"/>
    <geom name="box_48" type="box" conaffinity="1" pos="0 0 -10" size=".2 .8 .2" material="grid" rgba="1 0 0 1"/>
    <geom name="box_49" type="box" conaffinity="1" pos="0 0 -10" size=".2 .8 .2" material="grid" rgba="1 0 0 1"/>

    <geom name="box_50" type="box" conaffinity="1" pos="0 0 -10" size=".2 .8 .2" material="grid" rgba="1 0 0 1"/>
    <geom name="box_51" type="box" conaffinity="1" pos="0 0 -10" size=".2 .8 .2" material="grid" rgba="1 0 0 1"/>
    <geom name="box_52" type="box" conaffinity="1" pos="0 0 -10" size=".2 .8 .2" material="grid" rgba="1 0 0 1"/>
    <geom name="box_53" type="box" conaffinity="1" pos="0 0 -10" size=".2 .8 .2" material="grid" rgba="1 0 0 1"/>
    <geom name="box_54" type="box" conaffinity="1" pos="0 0 -10" size=".2 .8 .2" material="grid" rgba="1 0 0 1"/>
    <geom name="box_55" type="box" conaffinity="1" pos="0 0 -10" size=".2 .8 .2" material="grid" rgba="1 0 0 1"/>
    <geom name="box_56" type="box" conaffinity="1" pos="0 0 -10" size=".2 .8 .2" material="grid" rgba="1 0 0 1"/>
    <geom name="box_57" type="box" conaffinity="1" pos="0 0 -10" size=".2 .8 .2" material="grid" rgba="1 0 0 1"/>
    <geom name="box_58" type="box" conaffinity="1" pos="0 0 -10" size=".2 .8 .2" material="grid" rgba="1 0 0 1"/>
    <geom name="box_59" type="box" conaffinity="1" pos="0 0 -10" size=".2 .8 .2" material="grid" rgba="1 0 0 1"/>
    <geom name="box_60" type="box" conaffinity="1" pos="0 0 -10" size=".2 .8 .2" material="grid" rgba="1 0 0 1"/>
    <geom name="box_61" type="box" conaffinity="1" pos="0 0 -10" size=".2 .8 .2" material="grid" rgba="1 0 0 1"/>
    <geom name="box_62" type="box" conaffinity="1" pos="0 0 -10" size=".2 .8 .2" material="grid" rgba="1 0 0 1"/>
    <geom name="box_63" type="box" conaffinity="1" pos="0 0 -10" size=".2 .8 .2" material="grid" rgba="1 0 0 1"/>
    <geom name="box_64" type="box" conaffinity="1" pos="0 0 -10" size=".2 .8 .2" material="grid" rgba="1 0 0 1"/>
    <geom name="box_65" type="box" conaffinity="1" pos="0 0 -10" size=".2 .8 .2" material="grid" rgba="1 0 0 1"/>
    <geom name="box_66" type="box" conaffinity="1" pos="0 0 -10" size=".2 .8 .2" material="grid" rgba="1 0 0 1"/>
    <geom name="box_67" type="box" conaffinity="1" pos="0 0 -10" size=".2 .8 .2" material="grid" rgba="1 0 0 1"/>
    <geom name="box_68" type="box" conaffinity="1" pos="0 0 -10" size=".2 .8 .2" material="grid" rgba="1 0 0 1"/>
    <geom name="box_69" type="box" conaffinity="1" pos="0 0 -10" size=".2 .8 .2" material="grid" rgba="1 0 0 1"/>
    <geom name="box_70" type="box" conaffinity="1" pos="0 0 -10" size=".2 .8 .2" material="grid" rgba="1 0 0 1"/>
    <geom name="box_71" type="box" conaffinity="1" pos="0 0 -10" size=".2 .8 .2" material="grid" rgba="1 0 0 1"/>
    <geom name="box_72" type="box" conaffinity="1" pos="0 0 -10" size=".2 .8 .2" material="grid" rgba="1 0 0 1"/>
    <geom name="box_73" type="box" conaffinity="1" pos="0 0 -10" size=".2 .8 .2" material="grid" rgba="1 0 0 1"/>
    <geom name="box_74" type="box" conaffinity="1" pos="0 0 -10" size=".2 .8 .2" material="grid" rgba="1 0 0 1"/>

    <geom name="box_75" type="box" conaffinity="1" pos="0 0 -10" size=".2 .8 .2" material="grid" rgba="1 0 0 1"/>
    <geom name="box_76" type="box" conaffinity="1" pos="0 0 -10" size=".2 .8 .2" material="grid" rgba="1 0 0 1"/>
    <geom name="box_77" type="box" conaffinity="1" pos="0 0 -10" size=".2 .8 .2" material="grid" rgba="1 0 0 1"/>
    <geom name="box_78" type="box" conaffinity="1" pos="0 0 -10" size=".2 .8 .2" material="grid" rgba="1 0 0 1"/>
    <geom name="box_79" type="box" conaffinity="1" pos="0 0 -10" size=".2 .8 .2" material="grid" rgba="1 0 0 1"/>
    <geom name="box_80" type="box" conaffinity="1" pos="0 0 -10" size=".2 .8 .2" material="grid" rgba="1 0 0 1"/>
    <geom name="box_81" type="box" conaffinity="1" pos="0 0 -10" size=".2 .8 .2" material="grid" rgba="1 0 0 1"/>
    <geom name="box_82" type="box" conaffinity="1" pos="0 0 -10" size=".2 .8 .2" material="grid" rgba="1 0 0 1"/>
    <geom name="box_83" type="box" conaffinity="1" pos="0 0 -10" size=".2 .8 .2" material="grid" rgba="1 0 0 1"/>
    <geom name="box_84" type="box" conaffinity="1" pos="0 0 -10" size=".2 .8 .2" material="grid" rgba="1 0 0 1"/>
    <geom name="box_85" type="box" conaffinity="1" pos="0 0 -10" size=".2 .8 .2" material="grid" rgba="1 0 0 1"/>
    <geom name="box_86" type="box" conaffinity="1" pos="0 0 -10" size=".2 .8 .2" material="grid" rgba="1 0 0 1"/>
    <geom name="box_87" type="box" conaffinity="1" pos="0 0 -10" size=".2 .8 .2" material="grid" rgba="1 0 0 1"/>
    <geom name="box_88" type="box" conaffinity="1" pos="0 0 -10" size=".2 .8 .2" material="grid" rgba="1 0 0 1"/>
    <geom name="box_89" type="box" conaffinity="1" pos="0 0 -10" size=".2 .8 .2" material="grid" rgba="1 0 0 1"/>
    <geom name="box_90" type="box" conaffinity="1" pos="0 0 -10" size=".2 .8 .2" material="grid" rgba="1 0 0 1"/>
    <geom name="box_91" type="box" conaffinity="1" pos="0 0 -10" size=".2 .8 .2" material="grid" rgba="1 0 0 1"/>
    <geom name="box_92" type="box" conaffinity="1" pos="0 0 -10" size=".2 .8 .2" material="grid" rgba="1 0 0 1"/>
    <geom name="box_93" type="box" conaffinity="1" pos="0 0 -10" size=".2 .8 .2" material="grid" rgba="1 0 0 1"/>
    <geom name="box_94" type="box" conaffinity="1" pos="0 0 -10" size=".2 .8 .2" material="grid" rgba="1 0 0 1"/>
    <geom name="box_95" type="box" conaffinity="1" pos="0 0 -10" size=".2 .8 .2" material="grid" rgba="1 0 0 1"/>
    <geom name="box_96" type="box" conaffinity="1" pos="0 0 -10" size=".2 .8 .2" material="grid" rgba="1 0 0 1"/>
    <geom name="box_97" type="box" conaffinity="1" pos="0 0 -10" size=".2 .8 .2" material="grid" rgba="1 0 0 1"/>
    <geom name="box_98" type="box" conaffinity="1" pos="0 0 -10" size=".2 .8 .2" material="grid" rgba="1 0 0 1"/>
    <geom name="box_99" type="box" conaffinity="1" pos="0 0 -10" size=".2 .8 .2" material="grid" rgba="1 0 0 1"/>

    <body name="torso" pos="0 0 1.3" childclass="walker">
      <light name="light" pos="0 0 2" mode="trackcom"/>
      <camera name="side" pos="0 -2 .7" euler="60 0 0" mode="trackcom"/>
      <camera name="back" pos="-1.8 -1.3 0.8" xyaxes="0.45 -0.9 0 0.3 0.15 0.94" mode="trackcom"/>
      <!--camera name="back" pos="-2 0 .5" xyaxes="0 -1 0 1 0 3" mode="trackcom"/-->
      <camera name="egocentric" pos="0 0 0" euler="0 300 -90 " fovy="70"/>
      <joint name="rootz" axis="0 0 1" type="slide" limited="false" armature="0" damping="0"/>
      <joint name="rootx" axis="1 0 0" type="slide" limited="false" armature="0" damping="0"/>
      <joint name="rooty" axis="0 1 0" type="hinge" limited="false" armature="0" damping="0"/>
      <geom name="torso" size="0.07 0.3"/>
      <body name="right_thigh" pos="0 -.05 -0.3">
        <joint name="right_hip" range="-20 100"/>
        <geom name="right_thigh" pos="0 0 -0.225" size="0.05 0.225"/>
        <body name="right_leg" pos="0 0 -0.7">
          <joint name="right_knee" pos="0 0 0.25" range="-150 0"/>
          <geom name="right_leg" size="0.04 0.25"/>
          <body name="right_foot" pos="0.06 0 -0.25">
            <joint name="right_ankle" pos="-0.06 0 0" range="-45 45"/>
            <geom name="right_foot" zaxis="1 0 0" size="0.05 0.1"/>
          </body>
        </body>
      </body>
      <body name="left_thigh" pos="0 .05 -0.3" >
        <joint name="left_hip" range="-20 100"/>
        <geom name="left_thigh" pos="0 0 -0.225" size="0.05 0.225"/>
        <body name="left_leg" pos="0 0 -0.7">
          <joint name="left_knee" pos="0 0 0.25" range="-150 0"/>
          <geom name="left_leg" size="0.04 0.25"/>
          <body name="left_foot" pos="0.06 0 -0.25">
            <joint name="left_ankle" pos="-0.06 0 0" range="-45 45"/>
            <geom name="left_foot" zaxis="1 0 0" size="0.05 0.1"/>
          </body>
        </body>
      </body>
    </body>
  </worldbody>

  <sensor>
    <subtreelinvel name="torso_subtreelinvel" body="torso"/>
  </sensor>

  <actuator>
    <motor name="right_hip" joint="right_hip" gear="100"/>
    <motor name="right_knee" joint="right_knee" gear="50"/>
    <motor name="right_ankle" joint="right_ankle" gear="20"/>
    <motor name="left_hip" joint="left_hip" gear="100"/>
    <motor name="left_knee" joint="left_knee" gear="50"/>
    <motor name="left_ankle" joint="left_ankle" gear="20"/>
  </actuator>
</mujoco>