

<mujoco model="cheetah">
  <include file="./common_xml/skybox.xml"/>
  <include file="./common_xml/visual.xml"/>
  <include file="./common_xml/materials.xml"/>

  <compiler settotalmass="14"/>

  <default>
    <default class="cheetah">
      <joint limited="true" damping=".01" armature=".1" stiffness="8" type="hinge" axis="0 1 0"/>
      <geom contype="1" conaffinity="1" condim="3" friction=".4 .1 .1" material="self"/>
    </default>
    <default class="free">
      <joint limited="false" damping="0" armature="0" stiffness="0"/>
    </default>
    <motor ctrllimited="true" ctrlrange="-1 1"/>
  </default>

  <statistic center="0 0 .7" extent="2"/>

  <option timestep="0.01"/>

  <worldbody>
    <geom name="ground" type="plane" conaffinity="1" pos="98 0 0" size="200 .8 .5" material="grid"/>

    <geom name="box_00" type="box" conaffinity="1" pos="0 0 -10" size=".2 .8 .2" material="grid" rgba="1 0 0 1"/>
    <geom name="box_01" type="box" conaffinity="1" pos="0 0 -10" size=".2 .8 .2" material="grid" rgba="1 0 0 1"/>
    <geom name="box_02" type="box" conaffinity="1" pos="0 0 -10" size=".2 .8 .2" material="grid" rgba="1 0 0 1"/>
    <geom name="box_03" type="box" conaffinity="1" pos="0 0 -10" size=".2 .8 .2" material="grid" rgba="1 0 0 1"/>
    <geom name="box_04" type="box" conaffinity="1" pos="0 0 -10" size=".2 .8 .2" material="grid" rgba="1 0 0 1"/>
    <geom name="box_05" type="box" conaffinity="1" pos="0 0 -10" size=".2 .8 .2" material="grid" rgba="1 0 0 1"/>
    <geom name="box_06" type="box" conaffinity="1" pos="0 0 -10" size=".2 .8 .2" material="grid" rgba="1 0 0 1"/>
    <geom name="box_07" type="box" conaffinity="1" pos="0 0 -10" size=".2 .8 .2" material="grid" rgba="1 0 0 1"/>
    <geom name="box_08" type="box" conaffinity="1" pos="0 0 -10" size=".2 .8 .2" material="grid" rgba="1 0 0 1"/>
    <geom name="box_09" type="box" conaffinity="1" pos="0 0 -10" size=".2 .8 .2" material="grid" rgba="1 0 0 1"/>
    <geom name="box_10" type="box" conaffinity="1" pos="0 0 -10" size=".2 .8 .2" material="grid" rgba="1 0 0 1"/>
    <geom name="box_11" type="box" conaffinity="1" pos="0 0 -10" size=".2 .8 .2" material="grid" rgba="1 0 0 1"/>
    <geom name="box_12" type="box" conaffinity="1" pos="0 0 -10" size=".2 .8 .2" material="grid" rgba="1 0 0 1"/>
    <geom name="box_13" type="box" conaffinity="1" pos="0 0 -10" size=".2 .8 .2" material="grid" rgba="1 0 0 1"/>
    <geom name="box_14" type="box" conaffinity="1" pos="0 0 -10" size=".2 .8 .2" material="grid" rgba="1 0 0 1"/>
    <geom name="box_15" type="box" conaffinity="1" pos="0 0 -10" size=".2 .8 .2" material="grid" rgba="1 0 0 1"/>
    <geom name="box_16" type="box" conaffinity="1" pos="0 0 -10" size=".2 .8 .2" material="grid" rgba="1 0 0 1"/>
    <geom name="box_17" type="box" conaffinity="1" pos="0 0 -10" size=".2 .8 .2" material="grid" rgba="1 0 0 1"/>
    <geom name="box_18" type="box" conaffinity="1" pos="0 0 -10" size=".2 .8 .2" material="grid" rgba="1 0 0 1"/>
    <geom name="box_19" type="box" conaffinity="1" pos="0 0 -10" size=".2 .8 .2" material="grid" rgba="1 0 0 1"/>
    <geom name="box_20" type="box" conaffinity="1" pos="0 0 -10" size=".2 .8 .2" material="grid" rgba="1 0 0 1"/>
    <geom name="box_21" type="box" conaffinity="1" pos="0 0 -10" size=".2 .8 .2" material="grid" rgba="1 0 0 1"/>
    <geom name="box_22" type="box" conaffinity="1" pos="0 0 -10" size=".2 .8 .2" material="grid" rgba="1 0 0 1"/>
    <geom name="box_23" type="box" conaffinity="1" pos="0 0 -10" size=".2 .8 .2" material="grid" rgba="1 0 0 1"/>
    <geom name="box_24" type="box" conaffinity="1" pos="0 0 -10" size=".2 .8 .2" material="grid" rgba="1 0 0 1"/>

    <geom name="box_25" type="box" conaffinity="1" pos="0 0 -10" size=".2 .8 .2" material="grid" rgba="1 0 0 1"/>
    <geom name="box_26" type="box" conaffinity="1" pos="0 0 -10" size=".2 .8 .2" material="grid" rgba="1 0 0 1"/>
    <geom name="box_27" type="box" conaffinity="1" pos="0 0 -10" size=".2 .8 .2" material="grid" rgba="1 0 0 1"/>
    <geom name="box_28" type="box" conaffinity="1" pos="0 0 -10" size=".2 .8 .2" material="grid" rgba="1 0 0 1"/>
    <geom name="box_29" type="box" conaffinity="1" pos="0 0 -10" size=".2 .8 .2" material="grid" rgba="1 0 0 1"/>
    <geom name="box_30" type="box" conaffinity="1" pos="0 0 -10" size=".2 .8 .2" material="grid" rgba="1 0 0 1"/>
    <geom name="box_31" type="box" conaffinity="1" pos="0 0 -10" size=".2 .8 .2" material="grid" rgba="1 0 0 1"/>
    <geom name="box_32" type="box" conaffinity="1" pos="0 0 -10" size=".2 .8 .2" material="grid" rgba="1 0 0 1"/>
    <geom name="box_33" type="box" conaffinity="1" pos="0 0 -10" size=".2 .8 .2" material="grid" rgba="1 0 0 1"/>
    <geom name="box_34" type="box" conaffinity="1" pos="0 0 -10" size=".2 .8 .2" material="grid" rgba="1 0 0 1"/>
    <geom name="box_35" type="box" conaffinity="1" pos="0 0 -10" size=".2 .8 .2" material="grid" rgba="1 0 0 1"/>
    <geom name="box_36" type="box" conaffinity="1" pos="0 0 -10" size=".2 .8 .2" material="grid" rgba="1 0 0 1"/>
    <geom name="box_37" type="box" conaffinity="1" pos="0 0 -10" size=".2 .8 .2" material="grid" rgba="1 0 0 1"/>
    <geom name="box_38" type="box" conaffinity="1" pos="0 0 -10" size=".2 .8 .2" material="grid" rgba="1 0 0 1"/>
    <geom name="box_39" type="box" conaffinity="1" pos="0 0 -10" size=".2 .8 .2" material="grid" rgba="1 0 0 1"/>
    <geom name="box_40" type="box" conaffinity="1" pos="0 0 -10" size=".2 .8 .2" material="grid" rgba="1 0 0 1"/>
    <geom name="box_41" type="box" conaffinity="1" pos="0 0 -10" size=".2 .8 .2" material="grid" rgba="1 0 0 1"/>
    <geom name="box_42" type="box" conaffinity="1" pos="0 0 -10" size=".2 .8 .2" material="grid" rgba="1 0 0 1"/>
    <geom name="box_43" type="box" conaffinity="1" pos="0 0 -10" size=".2 .8 .2" material="grid" rgba="1 0 0 1"/>
    <geom name="box_44" type="box" conaffinity="1" pos="0 0 -10" size=".2 .8 .2" material="grid" rgba="1 0 0 1"/>
    <geom name="box_45" type="box" conaffinity="1" pos="0 0 -10" size=".2 .8 .2" material="grid" rgba="1 0 0 1"/>
    <geom name="box_46" type="box" conaffinity="1" pos="0 0 -10" size=".2 .8 .2" material="grid" rgba="1 0 0 1"/>
    <geom name="box_47" type="box" conaffinity="1" pos="0 0 -10" size=".2 .8 .2" material="grid" rgba="1 0 0 1"/>
    <geom name="box_48" type="box" conaffinity="1" pos="0 0 -10" size=".2 .8 .2" material="grid" rgba="1 0 0 1"/>
    <geom name="box_49" type="box" conaffinity="1" pos="0 0 -10" size=".2 .8 .2" material="grid" rgba="1 0 0 1"/>

    <geom name="box_50" type="box" conaffinity="1" pos="0 0 -10" size=".2 .8 .2" material="grid" rgba="1 0 0 1"/>
    <geom name="box_51" type="box" conaffinity="1" pos="0 0 -10" size=".2 .8 .2" material="grid" rgba="1 0 0 1"/>
    <geom name="box_52" type="box" conaffinity="1" pos="0 0 -10" size=".2 .8 .2" material="grid" rgba="1 0 0 1"/>
    <geom name="box_53" type="box" conaffinity="1" pos="0 0 -10" size=".2 .8 .2" material="grid" rgba="1 0 0 1"/>
    <geom name="box_54" type="box" conaffinity="1" pos="0 0 -10" size=".2 .8 .2" material="grid" rgba="1 0 0 1"/>
    <geom name="box_55" type="box" conaffinity="1" pos="0 0 -10" size=".2 .8 .2" material="grid" rgba="1 0 0 1"/>
    <geom name="box_56" type="box" conaffinity="1" pos="0 0 -10" size=".2 .8 .2" material="grid" rgba="1 0 0 1"/>
    <geom name="box_57" type="box" conaffinity="1" pos="0 0 -10" size=".2 .8 .2" material="grid" rgba="1 0 0 1"/>
    <geom name="box_58" type="box" conaffinity="1" pos="0 0 -10" size=".2 .8 .2" material="grid" rgba="1 0 0 1"/>
    <geom name="box_59" type="box" conaffinity="1" pos="0 0 -10" size=".2 .8 .2" material="grid" rgba="1 0 0 1"/>
    <geom name="box_60" type="box" conaffinity="1" pos="0 0 -10" size=".2 .8 .2" material="grid" rgba="1 0 0 1"/>
    <geom name="box_61" type="box" conaffinity="1" pos="0 0 -10" size=".2 .8 .2" material="grid" rgba="1 0 0 1"/>
    <geom name="box_62" type="box" conaffinity="1" pos="0 0 -10" size=".2 .8 .2" material="grid" rgba="1 0 0 1"/>
    <geom name="box_63" type="box" conaffinity="1" pos="0 0 -10" size=".2 .8 .2" material="grid" rgba="1 0 0 1"/>
    <geom name="box_64" type="box" conaffinity="1" pos="0 0 -10" size=".2 .8 .2" material="grid" rgba="1 0 0 1"/>
    <geom name="box_65" type="box" conaffinity="1" pos="0 0 -10" size=".2 .8 .2" material="grid" rgba="1 0 0 1"/>
    <geom name="box_66" type="box" conaffinity="1" pos="0 0 -10" size=".2 .8 .2" material="grid" rgba="1 0 0 1"/>
    <geom name="box_67" type="box" conaffinity="1" pos="0 0 -10" size=".2 .8 .2" material="grid" rgba="1 0 0 1"/>
    <geom name="box_68" type="box" conaffinity="1" pos="0 0 -10" size=".2 .8 .2" material="grid" rgba="1 0 0 1"/>
    <geom name="box_69" type="box" conaffinity="1" pos="0 0 -10" size=".2 .8 .2" material="grid" rgba="1 0 0 1"/>
    <geom name="box_70" type="box" conaffinity="1" pos="0 0 -10" size=".2 .8 .2" material="grid" rgba="1 0 0 1"/>
    <geom name="box_71" type="box" conaffinity="1" pos="0 0 -10" size=".2 .8 .2" material="grid" rgba="1 0 0 1"/>
    <geom name="box_72" type="box" conaffinity="1" pos="0 0 -10" size=".2 .8 .2" material="grid" rgba="1 0 0 1"/>
    <geom name="box_73" type="box" conaffinity="1" pos="0 0 -10" size=".2 .8 .2" material="grid" rgba="1 0 0 1"/>
    <geom name="box_74" type="box" conaffinity="1" pos="0 0 -10" size=".2 .8 .2" material="grid" rgba="1 0 0 1"/>

    <geom name="box_75" type="box" conaffinity="1" pos="0 0 -10" size=".2 .8 .2" material="grid" rgba="1 0 0 1"/>
    <geom name="box_76" type="box" conaffinity="1" pos="0 0 -10" size=".2 .8 .2" material="grid" rgba="1 0 0 1"/>
    <geom name="box_77" type="box" conaffinity="1" pos="0 0 -10" size=".2 .8 .2" material="grid" rgba="1 0 0 1"/>
    <geom name="box_78" type="box" conaffinity="1" pos="0 0 -10" size=".2 .8 .2" material="grid" rgba="1 0 0 1"/>
    <geom name="box_79" type="box" conaffinity="1" pos="0 0 -10" size=".2 .8 .2" material="grid" rgba="1 0 0 1"/>
    <geom name="box_80" type="box" conaffinity="1" pos="0 0 -10" size=".2 .8 .2" material="grid" rgba="1 0 0 1"/>
    <geom name="box_81" type="box" conaffinity="1" pos="0 0 -10" size=".2 .8 .2" material="grid" rgba="1 0 0 1"/>
    <geom name="box_82" type="box" conaffinity="1" pos="0 0 -10" size=".2 .8 .2" material="grid" rgba="1 0 0 1"/>
    <geom name="box_83" type="box" conaffinity="1" pos="0 0 -10" size=".2 .8 .2" material="grid" rgba="1 0 0 1"/>
    <geom name="box_84" type="box" conaffinity="1" pos="0 0 -10" size=".2 .8 .2" material="grid" rgba="1 0 0 1"/>
    <geom name="box_85" type="box" conaffinity="1" pos="0 0 -10" size=".2 .8 .2" material="grid" rgba="1 0 0 1"/>
    <geom name="box_86" type="box" conaffinity="1" pos="0 0 -10" size=".2 .8 .2" material="grid" rgba="1 0 0 1"/>
    <geom name="box_87" type="box" conaffinity="1" pos="0 0 -10" size=".2 .8 .2" material="grid" rgba="1 0 0 1"/>
    <geom name="box_88" type="box" conaffinity="1" pos="0 0 -10" size=".2 .8 .2" material="grid" rgba="1 0 0 1"/>
    <geom name="box_89" type="box" conaffinity="1" pos="0 0 -10" size=".2 .8 .2" material="grid" rgba="1 0 0 1"/>
    <geom name="box_90" type="box" conaffinity="1" pos="0 0 -10" size=".2 .8 .2" material="grid" rgba="1 0 0 1"/>
    <geom name="box_91" type="box" conaffinity="1" pos="0 0 -10" size=".2 .8 .2" material="grid" rgba="1 0 0 1"/>
    <geom name="box_92" type="box" conaffinity="1" pos="0 0 -10" size=".2 .8 .2" material="grid" rgba="1 0 0 1"/>
    <geom name="box_93" type="box" conaffinity="1" pos="0 0 -10" size=".2 .8 .2" material="grid" rgba="1 0 0 1"/>
    <geom name="box_94" type="box" conaffinity="1" pos="0 0 -10" size=".2 .8 .2" material="grid" rgba="1 0 0 1"/>
    <geom name="box_95" type="box" conaffinity="1" pos="0 0 -10" size=".2 .8 .2" material="grid" rgba="1 0 0 1"/>
    <geom name="box_96" type="box" conaffinity="1" pos="0 0 -10" size=".2 .8 .2" material="grid" rgba="1 0 0 1"/>
    <geom name="box_97" type="box" conaffinity="1" pos="0 0 -10" size=".2 .8 .2" material="grid" rgba="1 0 0 1"/>
    <geom name="box_98" type="box" conaffinity="1" pos="0 0 -10" size=".2 .8 .2" material="grid" rgba="1 0 0 1"/>
    <geom name="box_99" type="box" conaffinity="1" pos="0 0 -10" size=".2 .8 .2" material="grid" rgba="1 0 0 1"/>

    <body name="torso" pos="0 0 .7" childclass="cheetah">
      <light name="light" pos="0 0 2" mode="trackcom"/>
      <camera name="side" pos="0 -3 0" quat="0.707 0.707 0 0" mode="trackcom"/>
      <camera name="back" pos="-1.8 -1.3 0.8" xyaxes="0.45 -0.9 0 0.3 0.15 0.94" mode="trackcom"/>
      <camera name="egocentric" pos="0.6 0 0.1" euler="0 300 -90 " fovy="70"/>
      <joint name="rootx" type="slide" axis="1 0 0" class="free"/>
      <joint name="rootz" type="slide" axis="0 0 1" class="free"/>
      <joint name="rooty" type="hinge" axis="0 1 0" class="free"/>
      <geom name="torso" type="capsule" fromto="-.5 0 0 .5 0 0" size="0.046"/>
      <geom name="head" type="capsule" pos=".6 0 .1" euler="0 50 0" size="0.046 .15"/>
      <body name="bthigh" pos="-.5 0 0">
        <joint name="bthigh" range="-30 60" stiffness="240" damping="6"/>
        <geom name="bthigh" type="capsule" pos=".1 0 -.13" euler="0 -218 0" size="0.046 .145"/>
        <body name="bshin" pos=".16 0 -.25">
          <joint name="bshin" range="-50 50" stiffness="180" damping="4.5"/>
          <geom name="bshin" type="capsule" pos="-.14 0 -.07" euler="0 -116 0" size="0.046 .15"/>
          <body name="bfoot" pos="-.28 0 -.14">
            <joint name="bfoot" range="-230 50" stiffness="120" damping="3"/>
            <geom name="bfoot" type="capsule" pos=".03 0 -.097" euler="0 -15 0" size="0.046 .094"/>
          </body>
        </body>
      </body>
      <body name="fthigh" pos=".5 0 0">
        <joint name="fthigh" range="-57 .40" stiffness="180" damping="4.5"/>
        <geom name="fthigh" type="capsule" pos="-.07 0 -.12" euler="0 30 0" size="0.046 .133"/>
        <body name="fshin" pos="-.14 0 -.24">
          <joint name="fshin" range="-70 50" stiffness="120" damping="3"/>
          <geom name="fshin" type="capsule" pos=".065 0 -.09" euler="0 -34 0" size="0.046 .106"/>
          <body name="ffoot" pos=".13 0 -.18">
            <joint name="ffoot" range="-28 28" stiffness="60" damping="1.5"/>
            <geom name="ffoot" type="capsule" pos=".045 0 -.07" euler="0 -34 0" size="0.046 .07"/>
          </body>
        </body>
      </body>
    </body>
  </worldbody>

  <sensor>
    <subtreelinvel name="torso_subtreelinvel" body="torso"/>
  </sensor>

  <actuator>
    <motor name="bthigh" joint="bthigh" gear="120" />
    <motor name="bshin" joint="bshin" gear="90" />
    <motor name="bfoot" joint="bfoot" gear="60" />
    <motor name="fthigh" joint="fthigh" gear="90" />
    <motor name="fshin" joint="fshin" gear="60" />
    <motor name="ffoot" joint="ffoot" gear="30" />
  </actuator>
</mujoco>